Workbook

Sheet pricing_db
A1: model | B1: prompt | C1: completion | D1: image | E1: audio | F1: internal_reasoning | G1: input_cache_read | H1: input_cache_write | I1: web_search | J1: 套餐A | K1: 套餐B | L1: 套餐C
A2: anthropic/claude-3.5-haiku | B2: 0.8 | C2: 4 | G2: 0.08 | H2: 1 | I2: 10 | J2: 0 | K2: 0 | L2: 0
A3: anthropic/claude-3.5-sonnet | B3: 6 | C3: 30 | G3: 0.6 | H3: 7.5 | J3: 0 | K3: 0 | L3: 0
A4: anthropic/claude-3.7-sonnet | B4: 3 | C4: 15 | G4: 0.3 | H4: 3.75 | I4: 10 | J4: 0 | K4: 1 | L4: 1
A5: anthropic/claude-3.7-sonnet:thinking | B5: 3 | C5: 15 | G5: 0.3 | H5: 3.75 | I5: 10 | J5: 0 | K5: 0 | L5: 0
A6: anthropic/claude-3-haiku | B6: 0.25 | C6: 1.25 | G6: 0.03 | H6: 0.3 | J6: 0 | K6: 0 | L6: 0
A7: anthropic/claude-haiku-4.5 | B7: 1 | C7: 5 | G7: 0.1 | H7: 1.25 | I7: 10 | J7: 1 | K7: 1 | L7: 1
A8: anthropic/claude-opus-4 | B8: 15 | C8: 75 | G8: 1.5 | H8: 18.75 | I8: 10 | J8: 0 | K8: 0 | L8: 0
A9: anthropic/claude-opus-4.1 | B9: 15 | C9: 75 | G9: 1.5 | H9: 18.75 | I9: 10 | J9: 0 | K9: 0 | L9: 0
A10: anthropic/claude-opus-4.5 | B10: 5 | C10: 25 | G10: 0.5 | H10: 6.25 | I10: 10 | J10: 0 | K10: 0 | L10: 0
A11: anthropic/claude-opus-4.6 | B11: 5 | C11: 25 | G11: 0.5 | H11: 6.25 | I11: 10 | J11: 0 | K11: 0 | L11: 1
A12: anthropic/claude-sonnet-4.6 | B12: 3 | C12: 15 | G12: 0.3 | H12: 3.75 | I12: 10 | J12: 0 | K12: 1 | L12: 1
A13: google/gemini-2.0-flash-001 | B13: 0.1 | C13: 0.4 | D13: 0.1 | E13: 0.7 | F13: 0.4 | G13: 0.025 | H13: 0.083333333 | J13: 1 | K13: 1 | L13: 1
A14: google/gemini-2.0-flash-lite-001 | B14: 0.075 | C14: 0.3 | D14: 0.075 | E14: 0.075 | F14: 0.3 | J14: 0 | K14: 0 | L14: 0
A15: google/gemini-2.5-flash | B15: 0.3 | C15: 2.5 | D15: 0.3 | E15: 1 | F15: 2.5 | G15: 0.03 | H15: 0.083333333 | J15: 0 | K15: 1 | L15: 1
A16: google/gemini-2.5-flash-lite-preview-09-2025 | B16: 0.1 | C16: 0.4 | D16: 0.1 | E16: 0.3 | F16: 0.4 | G16: 0.01 | H16: 0.083333333 | J16: 0 | K16: 0 | L16: 0
A17: google/gemini-2.5-pro-preview | B17: 1.25 | C17: 10 | D17: 1.25 | E17: 1.25 | F17: 10 | G17: 0.125 | H17: 0.375 | J17: 0 | K17: 0 | L17: 0
A18: google/gemini-3.1-flash-image-preview | B18: 0.5 | C18: 3 | J18: 0 | K18: 0 | L18: 0
A19: google/gemini-3.1-flash-lite-preview | B19: 0.25 | C19: 1.5 | D19: 0.25 | E19: 0.5 | F19: 1.5 | G19: 0.025 | H19: 0.083333333 | J19: 0 | K19: 0 | L19: 0
A20: google/gemini-3.1-pro-preview | B20: 2 | C20: 12 | D20: 2 | E20: 2 | F20: 12 | G20: 0.2 | H20: 0.375 | J20: 0 | K20: 0 | L20: 0
A21: google/gemini-3-flash-preview | B21: 0.5 | C21: 3 | D21: 0.5 | E21: 1 | F21: 3 | G21: 0.05 | H21: 0.083333333 | J21: 0 | K21: 0 | L21: 0
A22: google/gemini-3-pro-preview | B22: 2 | C22: 12 | D22: 2 | E22: 2 | F22: 12 | G22: 0.2 | H22: 0.375 | J22: 0 | K22: 0 | L22: 0
A23: google/gemma-3-27b-it | B23: 0.03 | C23: 0.11 | G23: 0.015 | J23: 0 | K23: 0 | L23: 0
A24: google/gemma-3-4b-it | B24: 0.04 | C24: 0.08 | J24: 0 | K24: 0 | L24: 0
A25: google/gemma-3n-e2b-it:free | B25: 0 | C25: 0 | J25: 0 | K25: 0 | L25: 0
A26: google/gemma-3n-e4b-it | B26: 0.02 | C26: 0.04 | J26: 0 | K26: 0 | L26: 0
A27: openai/gpt-3.5-turbo-0613 | B27: 1 | C27: 2 | J27: 0 | K27: 0 | L27: 0
A28: openai/gpt-4.1 | B28: 2 | C28: 8 | G28: 0.5 | I28: 10 | J28: 0 | K28: 1 | L28: 1
A29: openai/gpt-4.1-mini | B29: 0.4 | C29: 1.6 | G29: 0.1 | I29: 10 | J29: 1 | K29: 1 | L29: 1
A30: openai/gpt-4o-mini | B30: 0.15 | C30: 0.6 | G30: 0.075 | J30: 0 | K30: 0 | L30: 0
A31: openai/gpt-4-turbo | B31: 10 | C31: 30 | J31: 0 | K31: 0 | L31: 0
A32: openai/gpt-5.1-codex | B32: 1.25 | C32: 10 | G32: 0.125 | J32: 0 | K32: 0 | L32: 0
A33: openai/gpt-5.1 | B33: 1.25 | C33: 10 | G33: 0.125 | I33: 10 | J33: 0 | K33: 0 | L33: 1
A34: openai/gpt-5.4 | B34: 2.5 | C34: 15 | G34: 0.25 | I34: 10 | J34: 0 | K34: 0 | L34: 0
A35: openai/gpt-5-image | B35: 10 | C35: 10 | G35: 1.25 | I35: 10 | J35: 0 | K35: 0 | L35: 0
A36: openai/gpt-5-mini | B36: 0.25 | C36: 2 | G36: 0.025 | I36: 10 | J36: 0 | K36: 0 | L36: 0
A37: openai/gpt-5-nano | B37: 0.05 | C37: 0.4 | G37: 0.005 | I37: 10 | J37: 0 | K37: 0 | L37: 0
A38: openai/gpt-oss-120b | B38: 0.039 | C38: 0.19 | J38: 0 | K38: 0 | L38: 0
A39: openai/o3 | B39: 2 | C39: 8 | G39: 0.5 | I39: 10 | J39: 0 | K39: 0 | L39: 1
A40: openai/o3-mini | B40: 1.1 | C40: 4.4 | G40: 0.55 | J40: 0 | K40: 0 | L40: 0
...

Sheet 成本汇总
A1: 模型/指标 | B1: 套餐A | C1: 套餐B | D1: 套餐C
A2: ── 选用模型 prompt ($/1M)
A3: anthropic/claude-3.7-sonnet | B3: — | C3: =pricing_db!B4 -> 3 | D3: =pricing_db!B4 -> 3
A4: anthropic/claude-haiku-4.5 | B4: =pricing_db!B7 -> 1 | C4: =pricing_db!B7 -> 1 | D4: =pricing_db!B7 -> 1
A5: anthropic/claude-opus-4.6 | B5: — | C5: — | D5: =pricing_db!B11 -> 5
A6: anthropic/claude-sonnet-4.6 | B6: — | C6: =pricing_db!B12 -> 3 | D6: =pricing_db!B12 -> 3
A7: google/gemini-2.0-flash-001 | B7: =pricing_db!B13 -> 0.1 | C7: =pricing_db!B13 -> 0.1 | D7: =pricing_db!B13 -> 0.1
A8: google/gemini-2.5-flash | B8: — | C8: =pricing_db!B15 -> 0.3 | D8: =pricing_db!B15 -> 0.3
A9: openai/gpt-4.1 | B9: — | C9: =pricing_db!B28 -> 2 | D9: =pricing_db!B28 -> 2
A10: openai/gpt-4.1-mini | B10: =pricing_db!B29 -> 0.4 | C10: =pricing_db!B29 -> 0.4 | D10: =pricing_db!B29 -> 0.4
A11: openai/gpt-5.1 | B11: — | C11: — | D11: =pricing_db!B33 -> 1.25
A12: openai/o3 | B12: — | C12: — | D12: =pricing_db!B39 -> 2
A14: ── 选用模型 completion ($/1M)
A15: anthropic/claude-3.7-sonnet | B15: — | C15: =pricing_db!C4 -> 15 | D15: =pricing_db!C4 -> 15
A16: anthropic/claude-haiku-4.5 | B16: =pricing_db!C7 -> 5 | C16: =pricing_db!C7 -> 5 | D16: =pricing_db!C7 -> 5
A17: anthropic/claude-opus-4.6 | B17: — | C17: — | D17: =pricing_db!C11 -> 25
A18: anthropic/claude-sonnet-4.6 | B18: — | C18: =pricing_db!C12 -> 15 | D18: =pricing_db!C12 -> 15
A19: google/gemini-2.0-flash-001 | B19: =pricing_db!C13 -> 0.4 | C19: =pricing_db!C13 -> 0.4 | D19: =pricing_db!C13 -> 0.4
A20: google/gemini-2.5-flash | B20: — | C20: =pricing_db!C15 -> 2.5 | D20: =pricing_db!C15 -> 2.5
A21: openai/gpt-4.1 | B21: — | C21: =pricing_db!C28 -> 8 | D21: =pricing_db!C28 -> 8
A22: openai/gpt-4.1-mini | B22: =pricing_db!C29 -> 1.6 | C22: =pricing_db!C29 -> 1.6 | D22: =pricing_db!C29 -> 1.6
A23: openai/gpt-5.1 | B23: — | C23: — | D23: =pricing_db!C33 -> 10
A24: openai/o3 | B24: — | C24: — | D24: =pricing_db!C39 -> 8
A26: ── 均价 & 成本估算
A27: 用量假设：月均输入 300K tokens，输出 100K tokens
A28: 平均 prompt ($/1M) | B28: =(pricing_db!B7+pricing_db!B13+pricing_db!B29)/3 -> 0.5 | C28: =(pricing_db!B4+pricing_db!B7+pricing_db!B12+pricing_db!B13+pricing_db!B15+pricing_db!B28+pricing_db!B29)/7 -> 1.4 | D28: =(pricing_db!B4+pricing_db!B7+pricing_db!B11+pricing_db!B12+pricing_db!B13+pricing_db!B15+pricing_db!B28+pricing_db!B29+pricing_db!B33+pricing_db!B39)/10 -> 1.805
A29: 平均 completion ($/1M) | B29: =(pricing_db!C7+pricing_db!C13+pricing_db!C29)/3 -> 2.3333333 | C29: =(pricing_db!C4+pricing_db!C7+pricing_db!C12+pricing_db!C13+pricing_db!C15+pricing_db!C28+pricing_db!C29)/7 -> 6.7857143 | D29: =(pricing_db!C4+pricing_db!C7+pricing_db!C11+pricing_db!C12+pricing_db!C13+pricing_db!C15+pricing_db!C28+pricing_db!C29+pricing_db!C33+pricing_db!C39)/10 -> 9.05
A30: 月API成本/用户（元，×7.3） | B30: =(((pricing_db!B7+pricing_db!B13+pricing_db!B29)/3)*300/1000+((pricing_db!C7+pricing_db!C13+pricing_db!C29)/3)*100/1000)*7.3 -> 2.7983333 | C30: =(((pricing_db!B4+pricing_db!B7+pricing_db!B12+pricing_db!B13+pricing_db!B15+pricing_db!B28+pricing_db!B29)/7)*300/1000+((pricing_db!C4+pricing_db!C7+pricing_db!C12+pricing_db!C13+pricing_db!C15+pricing_db!C28+pricing_db!C29)/7)*100/1000)*7.3 -> 8.0195714 | D30: =(((pricing_db!B4+pricing_db!B7+pricing_db!B11+pricing_db!B12+pricing_db!B13+pricing_db!B15+pricing_db!B28+pricing_db!B29+pricing_db!B33+pricing_db!B39)/10)*300/1000+((pricing_db!C4+pricing_db!C7+pricing_db!C11+pricing_db!C12+pricing_db!C13+pricing_db!C15+pricing_db!C28+pricing_db!C29+pricing_db!C33+pricing_db!C39)/10)*100/1000)*7.3 -> 10.55945
